Workbook
Name saraksts10: #REF!
Name saraksts10: #REF!
Name saraksts11: #REF!
Name saraksts11: #REF!
Name saraksts12: #REF!
Name saraksts12: #REF!
Name saraksts13: #REF!
Name saraksts13: #REF!
Name saraksts14: #REF!
Name saraksts14: #REF!
Name saraksts23: #REF!
Name saraksts23: #REF!
Name saraksts28: #REF!
Name saraksts28: #REF!
Name saraksts4: #REF!
Name saraksts4: #REF!
Name saraksts43: #REF!
Name saraksts43: #REF!
Name saraksts5: #REF!
Name saraksts5: #REF!
Name saraksts6: #REF!
Name saraksts6: #REF!
Name saraksts7: #REF!
Name saraksts7: #REF!
Name saraksts8: #REF!
Name saraksts8: #REF!
Name saraksts9: #REF!
Name saraksts9: #REF!

Sheet forma
A1: EE | C1: =tulkojums!A41 -> Materjaliandmeid on uuendatud | H1: 15.05.2026 | J1: ver.2.3.
A2: =tulkojums!A6 -> Tellimuse number | B2: LPA161890 | O2: Var aplīmēt 2 garās malas, ja šaurā ir >57mm
A3: =tulkojums!A25 -> Tellimuse kuupäev | B3: 2026-05-15T00:00:00Z | O3: Nevar izpildīt dēļ CNC ierobežojuma: MIN 40x155 mm; MAX 1600x3000 mm
A4: =tulkojums!A26 -> Klient | B4: PAKKUMINE
A5: =tulkojums!A27 -> E-mail | D5: =tulkojums!A28 -> Mob.
A6: =tulkojums!A7 -> Kliendiprojekt nr.
A7: =tulkojums!A8 -> Kliendi nr.
G8: =tulkojums!A21&tulkojums!A22&tulkojums!A23 -> N-ühetooniline dekoor; Y-paralleelne pikkusega;X-paralleelne laiusega | M8: =tulkojums!A33 -> Viga kontrollimisel
A9: =tulkojums!A9 -> Detaili nimetus | B9: =tulkojums!A31 -> Joonise nr * | C9: =tulkojums!A10 -> Tootekood | D9: =tulkojums!A11 -> Detaili mõõdud | H9: =tulkojums!A16 -> ABS servakantide paigaldamine | P9: =tulkojums!A40 -> Äärekontroll
D10: =tulkojums!A12 -> Pikkus Y | E10: =tulkojums!A13 -> Laius X | F10: =tulkojums!A14 -> Kogus | G10: =tulkojums!A15 -> Puidusüü asetsemine | H10: =tulkojums!A17 -> Pikkus Y1 | I10: =tulkojums!A18 -> Pikkus Y2 | J10: =tulkojums!A19 -> Laius X1 | K10: =tulkojums!A20 -> Laius X2 | M10: =tulkojums!A34 -> Materjali kontroll | N10: =tulkojums!A35 -> Koguse kontrollimine | O10: =tulkojums!A36 -> Kiudsuuna test | P10: =tulkojums!A37 -> Kaunistus ja laius | Q10: =tulkojums!A37 -> Kaunistus ja laius | R10: =tulkojums!A37 -> Kaunistus ja laius | S10: =tulkojums!A37 -> Kaunistus ja laius
A11: Detaili nimetus | C11: 73.F416.10 | D11: 2770 | E11: 1100 | F11: 2 | G11: Y | H11: 74R.F416.2.23 | I11: 74R.F416.2.23 | J11: 74R.F416.2.23 | K11: 74R.F416.2.23 | M11: =IF(ISBLANK(C11),"",IF(IFERROR(VLOOKUP(C11,DB_materiali!$A$2:$A$5000,1,FALSE),"Kļūda artikulā")=C11,"✔",tulkojums!A$42)) -> ✔ | N11: =IF(ISBLANK(C11),"",IF(ISNUMBER(F11)=TRUE,"✔",tulkojums!A$43)) -> ✔ | O11: =IF(ISBLANK(C11),"",IF(G11="Y","✔",IF(G11="X","✔",IF(G11="N","✔",tulkojums!A$44)))) -> ✔ | P11: =IF(ISBLANK(H11),"",IF(INDEX(DB_materiali!$E$2:$E$5000,MATCH($C11,DB_materiali!$A$2:$A$5000,0))>=INDEX(DB_malas!$C$2:$C$5000,MATCH(H11,DB_malas!$A$2:$A$5000,0)),IF(INDEX(DB_materiali!$E$2:$E$5000,MATCH($C11,DB_materiali!$A$2:$A$5000,0))<=INDEX(DB_malas!$D$2:$D$5000,MATCH(H11,DB_malas!$A$2:$A$5000,0)),IF(OR(INDEX(DB_materiali!$B$2:$B$5000,MATCH($C11,DB_materiali!$A$2:$A$5000,0))=INDEX(DB_malas!$B$2:$B$5000,MATCH(H11,DB_malas!$A$2:$A$5000,0)),$H11="ORG"),"✔",tulkojums!$A$38),tulkojums!$A$39),tulkojums!$A$39)) -> ✔ | Q11: =IF(ISBLANK(I11),"",IF(INDEX(DB_materiali!$E$2:$E$5000,MATCH($C11,DB_materiali!$A$2:$A$5000,0))>=INDEX(DB_malas!$C$2:$C$5000,MATCH(I11,DB_malas!$A$2:$A$5000,0)),IF(INDEX(DB_materiali!$E$2:$E$5000,MATCH($C11,DB_materiali!$A$2:$A$5000,0))<=INDEX(DB_malas!$D$2:$D$5000,MATCH(I11,DB_malas!$A$2:$A$5000,0)),IF(OR(INDEX(DB_materiali!$B$2:$B$5000,MATCH($C11,DB_materiali!$A$2:$A$5000,0))=INDEX(DB_malas!$B$2:$B$5000,MATCH(I11,DB_malas!$A$2:$A$5000,0)),$H11="ORG"),"✔",tulkojums!$A$38),tulkojums!$A$39),tulkojums!$A$39)) -> ✔ | R11: =IF(ISBLANK(J11),"",IF(INDEX(DB_materiali!$E$2:$E$5000,MATCH($C11,DB_materiali!$A$2:$A$5000,0))>=INDEX(DB_malas!$C$2:$C$5000,MATCH(J11,DB_malas!$A$2:$A$5000,0)),IF(INDEX(DB_materiali!$E$2:$E$5000,MATCH($C11,DB_materiali!$A$2:$A$5000,0))<=INDEX(DB_malas!$D$2:$D$5000,MATCH(J11,DB_malas!$A$2:$A$5000,0)),IF(INDEX(DB_materiali!$B$2:$B$5000,MATCH($C11,DB_materiali!$A$2:$A$5000,0))=INDEX(DB_malas!$B$2:$B$5000,MATCH(J11,DB_malas!$A$2:$A$5000,0)),"✔",tulkojums!$A$38),tulkojums!$A$39),tulkojums!$A$39)) -> ✔ | S11: =IF(ISBLANK(K11),"",IF(INDEX(DB_materiali!$E$2:$E$5000,MATCH($C11,DB_materiali!$A$2:$A$5000,0))>=INDEX(DB_malas!$C$2:$C$5000,MATCH(K11,DB_malas!$A$2:$A$5000,0)),IF(INDEX(DB_materiali!$E$2:$E$5000,MATCH($C11,DB_materiali!$A$2:$A$5000,0))<=INDEX(DB_malas!$D$2:$D$5000,MATCH(K11,DB_malas!$A$2:$A$5000,0)),IF(INDEX(DB_materiali!$B$2:$B$5000,MATCH($C11,DB_materiali!$A$2:$A$5000,0))=INDEX(DB_malas!$B$2:$B$5000,MATCH(K11,DB_malas!$A$2:$A$5000,0)),"✔",tulkojums!$A$38),tulkojums!$A$39),tulkojums!$A$39)) -> ✔
A12: Detaili nimetus | C12: 73.H1399.10 | D12: 2770 | E12: 1100 | F12: 18 | G12: Y | H12: 74R.H1399.2.23 | I12: 74R.H1399.2.23 | J12: 74R.H1399.2.23 | K12: 74R.H1399.2.23 | M12: =IF(ISBLANK(C12),"",IF(IFERROR(VLOOKUP(C12,DB_materiali!$A$2:$A$5000,1,FALSE),"Kļūda artikulā")=C12,"✔",tulkojums!A$42)) -> ✔ | N12: =IF(ISBLANK(C12),"",IF(ISNUMBER(F12)=TRUE,"✔",tulkojums!A$43)) -> ✔ | O12: =IF(ISBLANK(C12),"",IF(G12="Y","✔",IF(G12="X","✔",IF(G12="N","✔",tulkojums!A$44)))) -> ✔ | P12: =IF(ISBLANK(H12),"",IF(INDEX(DB_materiali!$E$2:$E$5000,MATCH($C12,DB_materiali!$A$2:$A$5000,0))>=INDEX(DB_malas!$C$2:$C$5000,MATCH(H12,DB_malas!$A$2:$A$5000,0)),IF(INDEX(DB_materiali!$E$2:$E$5000,MATCH($C12,DB_materiali!$A$2:$A$5000,0))<=INDEX(DB_malas!$D$2:$D$5000,MATCH(H12,DB_malas!$A$2:$A$5000,0)),IF(OR(INDEX(DB_materiali!$B$2:$B$5000,MATCH($C12,DB_materiali!$A$2:$A$5000,0))=INDEX(DB_malas!$B$2:$B$5000,MATCH(H12,DB_malas!$A$2:$A$5000,0)),$H12="ORG"),"✔",tulkojums!$A$38),tulkojums!$A$39),tulkojums!$A$39)) -> ✔ | Q12: =IF(ISBLANK(I12),"",IF(INDEX(DB_materiali!$E$2:$E$5000,MATCH($C12,DB_materiali!$A$2:$A$5000,0))>=INDEX(DB_malas!$C$2:$C$5000,MATCH(I12,DB_malas!$A$2:$A$5000,0)),IF(INDEX(DB_materiali!$E$2:$E$5000,MATCH($C12,DB_materiali!$A$2:$A$5000,0))<=INDEX(DB_malas!$D$2:$D$5000,MATCH(I12,DB_malas!$A$2:$A$5000,0)),IF(OR(INDEX(DB_materiali!$B$2:$B$5000,MATCH($C12,DB_materiali!$A$2:$A$5000,0))=INDEX(DB_malas!$B$2:$B$5000,MATCH(I12,DB_malas!$A$2:$A$5000,0)),$H12="ORG"),"✔",tulkojums!$A$38),tulkojums!$A$39),tulkojums!$A$39)) -> ✔ | R12: =IF(ISBLANK(J12),"",IF(INDEX(DB_materiali!$E$2:$E$5000,MATCH($C12,DB_materiali!$A$2:$A$5000,0))>=INDEX(DB_malas!$C$2:$C$5000,MATCH(J12,DB_malas!$A$2:$A$5000,0)),IF(INDEX(DB_materiali!$E$2:$E$5000,MATCH($C12,DB_materiali!$A$2:$A$5000,0))<=INDEX(DB_malas!$D$2:$D$5000,MATCH(J12,DB_malas!$A$2:$A$5000,0)),IF(INDEX(DB_materiali!$B$2:$B$5000,MATCH($C12,DB_materiali!$A$2:$A$5000,0))=INDEX(DB_malas!$B$2:$B$5000,MATCH(J12,DB_malas!$A$2:$A$5000,0)),"✔",tulkojums!$A$38),tulkojums!$A$39),tulkojums!$A$39)) -> ✔ | S12: =IF(ISBLANK(K12),"",IF(INDEX(DB_materiali!$E$2:$E$5000,MATCH($C12,DB_materiali!$A$2:$A$5000,0))>=INDEX(DB_malas!$C$2:$C$5000,MATCH(K12,DB_malas!$A$2:$A$5000,0)),IF(INDEX(DB_materiali!$E$2:$E$5000,MATCH($C12,DB_materiali!$A$2:$A$5000,0))<=INDEX(DB_malas!$D$2:$D$5000,MATCH(K12,DB_malas!$A$2:$A$5000,0)),IF(INDEX(DB_materiali!$B$2:$B$5000,MATCH($C12,DB_materiali!$A$2:$A$5000,0))=INDEX(DB_malas!$B$2:$B$5000,MATCH(K12,DB_malas!$A$2:$A$5000,0)),"✔",tulkojums!$A$38),tulkojums!$A$39),tulkojums!$A$39)) -> ✔
G13: =IF(ISBLANK(C13),"", IFERROR( IF( INDEX(DB_materiali!C$2:C$5000, MATCH(C13, DB_materiali!A$2:A$5000, 0) )="FALSE", "N", "Y" ), "") ) | M13: =IF(ISBLANK(C13),"",IF(IFERROR(VLOOKUP(C13,DB_materiali!$A$2:$A$5000,1,FALSE),"Kļūda artikulā")=C13,"✔",tulkojums!A$42)) | N13: =IF(ISBLANK(C13),"",IF(ISNUMBER(F13)=TRUE,"✔",tulkojums!A$43)) | O13: =IF(ISBLANK(C13),"",IF(G13="Y","✔",IF(G13="X","✔",IF(G13="N","✔",tulkojums!A$44)))) | P13: =IF(ISBLANK(H13),"",IF(INDEX(DB_materiali!$E$2:$E$5000,MATCH($C13,DB_materiali!$A$2:$A$5000,0))>=INDEX(DB_malas!$C$2:$C$5000,MATCH(H13,DB_malas!$A$2:$A$5000,0)),IF(INDEX(DB_materiali!$E$2:$E$5000,MATCH($C13,DB_materiali!$A$2:$A$5000,0))<=INDEX(DB_malas!$D$2:$D$5000,MATCH(H13,DB_malas!$A$2:$A$5000,0)),IF(OR(INDEX(DB_materiali!$B$2:$B$5000,MATCH($C13,DB_materiali!$A$2:$A$5000,0))=INDEX(DB_malas!$B$2:$B$5000,MATCH(H13,DB_malas!$A$2:$A$5000,0)),$H13="ORG"),"✔",tulkojums!$A$38),tulkojums!$A$39),tulkojums!$A$39)) | Q13: =IF(ISBLANK(I13),"",IF(INDEX(DB_materiali!$E$2:$E$5000,MATCH($C13,DB_materiali!$A$2:$A$5000,0))>=INDEX(DB_malas!$C$2:$C$5000,MATCH(I13,DB_malas!$A$2:$A$5000,0)),IF(INDEX(DB_materiali!$E$2:$E$5000,MATCH($C13,DB_materiali!$A$2:$A$5000,0))<=INDEX(DB_malas!$D$2:$D$5000,MATCH(I13,DB_malas!$A$2:$A$5000,0)),IF(OR(INDEX(DB_materiali!$B$2:$B$5000,MATCH($C13,DB_materiali!$A$2:$A$5000,0))=INDEX(DB_malas!$B$2:$B$5000,MATCH(I13,DB_malas!$A$2:$A$5000,0)),$H13="ORG"),"✔",tulkojums!$A$38),tulkojums!$A$39),tulkojums!$A$39)) | R13: =IF(ISBLANK(J13),"",IF(INDEX(DB_materiali!$E$2:$E$5000,MATCH($C13,DB_materiali!$A$2:$A$5000,0))>=INDEX(DB_malas!$C$2:$C$5000,MATCH(J13,DB_malas!$A$2:$A$5000,0)),IF(INDEX(DB_materiali!$E$2:$E$5000,MATCH($C13,DB_materiali!$A$2:$A$5000,0))<=INDEX(DB_malas!$D$2:$D$5000,MATCH(J13,DB_malas!$A$2:$A$5000,0)),IF(INDEX(DB_materiali!$B$2:$B$5000,MATCH($C13,DB_materiali!$A$2:$A$5000,0))=INDEX(DB_malas!$B$2:$B$5000,MATCH(J13,DB_malas!$A$2:$A$5000,0)),"✔",tulkojums!$A$38),tulkojums!$A$39),tulkojums!$A$39)) | S13: =IF(ISBLANK(K13),"",IF(INDEX(DB_materiali!$E$2:$E$5000,MATCH($C13,DB_materiali!$A$2:$A$5000,0))>=INDEX(DB_malas!$C$2:$C$5000,MATCH(K13,DB_malas!$A$2:$A$5000,0)),IF(INDEX(DB_materiali!$E$2:$E$5000,MATCH($C13,DB_materiali!$A$2:$A$5000,0))<=INDEX(DB_malas!$D$2:$D$5000,MATCH(K13,DB_malas!$A$2:$A$5000,0)),IF(INDEX(DB_materiali!$B$2:$B$5000,MATCH($C13,DB_materiali!$A$2:$A$5000,0))=INDEX(DB_malas!$B$2:$B$5000,MATCH(K13,DB_malas!$A$2:$A$5000,0)),"✔",tulkojums!$A$38),tulkojums!$A$39),tulkojums!$A$39))
G14: =IF(ISBLANK(C14),"", IFERROR( IF( INDEX(DB_materiali!C$2:C$5000, MATCH(C14, DB_materiali!A$2:A$5000, 0) )="FALSE", "N", "Y" ), "") ) | M14: =IF(ISBLANK(C14),"",IF(IFERROR(VLOOKUP(C14,DB_materiali!$A$2:$A$5000,1,FALSE),"Kļūda artikulā")=C14,"✔",tulkojums!A$42)) | N14: =IF(ISBLANK(C14),"",IF(ISNUMBER(F14)=TRUE,"✔",tulkojums!A$43)) | O14: =IF(ISBLANK(C14),"",IF(G14="Y","✔",IF(G14="X","✔",IF(G14="N","✔",tulkojums!A$44)))) | P14: =IF(ISBLANK(H14),"",IF(INDEX(DB_materiali!$E$2:$E$5000,MATCH($C14,DB_materiali!$A$2:$A$5000,0))>=INDEX(DB_malas!$C$2:$C$5000,MATCH(H14,DB_malas!$A$2:$A$5000,0)),IF(INDEX(DB_materiali!$E$2:$E$5000,MATCH($C14,DB_materiali!$A$2:$A$5000,0))<=INDEX(DB_malas!$D$2:$D$5000,MATCH(H14,DB_malas!$A$2:$A$5000,0)),IF(OR(INDEX(DB_materiali!$B$2:$B$5000,MATCH($C14,DB_materiali!$A$2:$A$5000,0))=INDEX(DB_malas!$B$2:$B$5000,MATCH(H14,DB_malas!$A$2:$A$5000,0)),$H14="ORG"),"✔",tulkojums!$A$38),tulkojums!$A$39),tulkojums!$A$39)) | Q14: =IF(ISBLANK(I14),"",IF(INDEX(DB_materiali!$E$2:$E$5000,MATCH($C14,DB_materiali!$A$2:$A$5000,0))>=INDEX(DB_malas!$C$2:$C$5000,MATCH(I14,DB_malas!$A$2:$A$5000,0)),IF(INDEX(DB_materiali!$E$2:$E$5000,MATCH($C14,DB_materiali!$A$2:$A$5000,0))<=INDEX(DB_malas!$D$2:$D$5000,MATCH(I14,DB_malas!$A$2:$A$5000,0)),IF(OR(INDEX(DB_materiali!$B$2:$B$5000,MATCH($C14,DB_materiali!$A$2:$A$5000,0))=INDEX(DB_malas!$B$2:$B$5000,MATCH(I14,DB_malas!$A$2:$A$5000,0)),$H14="ORG"),"✔",tulkojums!$A$38),tulkojums!$A$39),tulkojums!$A$39)) | R14: =IF(ISBLANK(J14),"",IF(INDEX(DB_materiali!$E$2:$E$5000,MATCH($C14,DB_materiali!$A$2:$A$5000,0))>=INDEX(DB_malas!$C$2:$C$5000,MATCH(J14,DB_malas!$A$2:$A$5000,0)),IF(INDEX(DB_materiali!$E$2:$E$5000,MATCH($C14,DB_materiali!$A$2:$A$5000,0))<=INDEX(DB_malas!$D$2:$D$5000,MATCH(J14,DB_malas!$A$2:$A$5000,0)),IF(INDEX(DB_materiali!$B$2:$B$5000,MATCH($C14,DB_materiali!$A$2:$A$5000,0))=INDEX(DB_malas!$B$2:$B$5000,MATCH(J14,DB_malas!$A$2:$A$5000,0)),"✔",tulkojums!$A$38),tulkojums!$A$39),tulkojums!$A$39)) | S14: =IF(ISBLANK(K14),"",IF(INDEX(DB_materiali!$E$2:$E$5000,MATCH($C14,DB_materiali!$A$2:$A$5000,0))>=INDEX(DB_malas!$C$2:$C$5000,MATCH(K14,DB_malas!$A$2:$A$5000,0)),IF(INDEX(DB_materiali!$E$2:$E$5000,MATCH($C14,DB_materiali!$A$2:$A$5000,0))<=INDEX(DB_malas!$D$2:$D$5000,MATCH(K14,DB_malas!$A$2:$A$5000,0)),IF(INDEX(DB_materiali!$B$2:$B$5000,MATCH($C14,DB_materiali!$A$2:$A$5000,0))=INDEX(DB_malas!$B$2:$B$5000,MATCH(K14,DB_malas!$A$2:$A$5000,0)),"✔",tulkojums!$A$38),tulkojums!$A$39),tulkojums!$A$39))
G15: =IF(ISBLANK(C15),"", IFERROR( IF( INDEX(DB_materiali!C$2:C$5000, MATCH(C15, DB_materiali!A$2:A$5000, 0) )="FALSE", "N", "Y" ), "") ) | M15: =IF(ISBLANK(C15),"",IF(IFERROR(VLOOKUP(C15,DB_materiali!$A$2:$A$5000,1,FALSE),"Kļūda artikulā")=C15,"✔",tulkojums!A$42)) | N15: =IF(ISBLANK(C15),"",IF(ISNUMBER(F15)=TRUE,"✔",tulkojums!A$43)) | O15: =IF(ISBLANK(C15),"",IF(G15="Y","✔",IF(G15="X","✔",IF(G15="N","✔",tulkojums!A$44)))) | P15: =IF(ISBLANK(H15),"",IF(INDEX(DB_materiali!$E$2:$E$5000,MATCH($C15,DB_materiali!$A$2:$A$5000,0))>=INDEX(DB_malas!$C$2:$C$5000,MATCH(H15,DB_malas!$A$2:$A$5000,0)),IF(INDEX(DB_materiali!$E$2:$E$5000,MATCH($C15,DB_materiali!$A$2:$A$5000,0))<=INDEX(DB_malas!$D$2:$D$5000,MATCH(H15,DB_malas!$A$2:$A$5000,0)),IF(OR(INDEX(DB_materiali!$B$2:$B$5000,MATCH($C15,DB_materiali!$A$2:$A$5000,0))=INDEX(DB_malas!$B$2:$B$5000,MATCH(H15,DB_malas!$A$2:$A$5000,0)),$H15="ORG"),"✔",tulkojums!$A$38),tulkojums!$A$39),tulkojums!$A$39)) | Q15: =IF(ISBLANK(I15),"",IF(INDEX(DB_materiali!$E$2:$E$5000,MATCH($C15,DB_materiali!$A$2:$A$5000,0))>=INDEX(DB_malas!$C$2:$C$5000,MATCH(I15,DB_malas!$A$2:$A$5000,0)),IF(INDEX(DB_materiali!$E$2:$E$5000,MATCH($C15,DB_materiali!$A$2:$A$5000,0))<=INDEX(DB_malas!$D$2:$D$5000,MATCH(I15,DB_malas!$A$2:$A$5000,0)),IF(OR(INDEX(DB_materiali!$B$2:$B$5000,MATCH($C15,DB_materiali!$A$2:$A$5000,0))=INDEX(DB_malas!$B$2:$B$5000,MATCH(I15,DB_malas!$A$2:$A$5000,0)),$H15="ORG"),"✔",tulkojums!$A$38),tulkojums!$A$39),tulkojums!$A$39)) | R15: =IF(ISBLANK(J15),"",IF(INDEX(DB_materiali!$E$2:$E$5000,MATCH($C15,DB_materiali!$A$2:$A$5000,0))>=INDEX(DB_malas!$C$2:$C$5000,MATCH(J15,DB_malas!$A$2:$A$5000,0)),IF(INDEX(DB_materiali!$E$2:$E$5000,MATCH($C15,DB_materiali!$A$2:$A$5000,0))<=INDEX(DB_malas!$D$2:$D$5000,MATCH(J15,DB_malas!$A$2:$A$5000,0)),IF(INDEX(DB_materiali!$B$2:$B$5000,MATCH($C15,DB_materiali!$A$2:$A$5000,0))=INDEX(DB_malas!$B$2:$B$5000,MATCH(J15,DB_malas!$A$2:$A$5000,0)),"✔",tulkojums!$A$38),tulkojums!$A$39),tulkojums!$A$39)) | S15: =IF(ISBLANK(K15),"",IF(INDEX(DB_materiali!$E$2:$E$5000,MATCH($C15,DB_materiali!$A$2:$A$5000,0))>=INDEX(DB_malas!$C$2:$C$5000,MATCH(K15,DB_malas!$A$2:$A$5000,0)),IF(INDEX(DB_materiali!$E$2:$E$5000,MATCH($C15,DB_materiali!$A$2:$A$5000,0))<=INDEX(DB_malas!$D$2:$D$5000,MATCH(K15,DB_malas!$A$2:$A$5000,0)),IF(INDEX(DB_materiali!$B$2:$B$5000,MATCH($C15,DB_materiali!$A$2:$A$5000,0))=INDEX(DB_malas!$B$2:$B$5000,MATCH(K15,DB_malas!$A$2:$A$5000,0)),"✔",tulkojums!$A$38),tulkojums!$A$39),tulkojums!$A$39))
G16: =IF(ISBLANK(C16),"", IFERROR( IF( INDEX(DB_materiali!C$2:C$5000, MATCH(C16, DB_materiali!A$2:A$5000, 0) )="FALSE", "N", "Y" ), "") ) | M16: =IF(ISBLANK(C16),"",IF(IFERROR(VLOOKUP(C16,DB_materiali!$A$2:$A$5000,1,FALSE),"Kļūda artikulā")=C16,"✔",tulkojums!A$42)) | N16: =IF(ISBLANK(C16),"",IF(ISNUMBER(F16)=TRUE,"✔",tulkojums!A$43)) | O16: =IF(ISBLANK(C16),"",IF(G16="Y","✔",IF(G16="X","✔",IF(G16="N","✔",tulkojums!A$44)))) | P16: =IF(ISBLANK(H16),"",IF(INDEX(DB_materiali!$E$2:$E$5000,MATCH($C16,DB_materiali!$A$2:$A$5000,0))>=INDEX(DB_malas!$C$2:$C$5000,MATCH(H16,DB_malas!$A$2:$A$5000,0)),IF(INDEX(DB_materiali!$E$2:$E$5000,MATCH($C16,DB_materiali!$A$2:$A$5000,0))<=INDEX(DB_malas!$D$2:$D$5000,MATCH(H16,DB_malas!$A$2:$A$5000,0)),IF(OR(INDEX(DB_materiali!$B$2:$B$5000,MATCH($C16,DB_materiali!$A$2:$A$5000,0))=INDEX(DB_malas!$B$2:$B$5000,MATCH(H16,DB_malas!$A$2:$A$5000,0)),$H16="ORG"),"✔",tulkojums!$A$38),tulkojums!$A$39),tulkojums!$A$39)) | Q16: =IF(ISBLANK(I16),"",IF(INDEX(DB_materiali!$E$2:$E$5000,MATCH($C16,DB_materiali!$A$2:$A$5000,0))>=INDEX(DB_malas!$C$2:$C$5000,MATCH(I16,DB_malas!$A$2:$A$5000,0)),IF(INDEX(DB_materiali!$E$2:$E$5000,MATCH($C16,DB_materiali!$A$2:$A$5000,0))<=INDEX(DB_malas!$D$2:$D$5000,MATCH(I16,DB_malas!$A$2:$A$5000,0)),IF(OR(INDEX(DB_materiali!$B$2:$B$5000,MATCH($C16,DB_materiali!$A$2:$A$5000,0))=INDEX(DB_malas!$B$2:$B$5000,MATCH(I16,DB_malas!$A$2:$A$5000,0)),$H16="ORG"),"✔",tulkojums!$A$38),tulkojums!$A$39),tulkojums!$A$39)) | R16: =IF(ISBLANK(J16),"",IF(INDEX(DB_materiali!$E$2:$E$5000,MATCH($C16,DB_materiali!$A$2:$A$5000,0))>=INDEX(DB_malas!$C$2:$C$5000,MATCH(J16,DB_malas!$A$2:$A$5000,0)),IF(INDEX(DB_materiali!$E$2:$E$5000,MATCH($C16,DB_materiali!$A$2:$A$5000,0))<=INDEX(DB_malas!$D$2:$D$5000,MATCH(J16,DB_malas!$A$2:$A$5000,0)),IF(INDEX(DB_materiali!$B$2:$B$5000,MATCH($C16,DB_materiali!$A$2:$A$5000,0))=INDEX(DB_malas!$B$2:$B$5000,MATCH(J16,DB_malas!$A$2:$A$5000,0)),"✔",tulkojums!$A$38),tulkojums!$A$39),tulkojums!$A$39)) | S16: =IF(ISBLANK(K16),"",IF(INDEX(DB_materiali!$E$2:$E$5000,MATCH($C16,DB_materiali!$A$2:$A$5000,0))>=INDEX(DB_malas!$C$2:$C$5000,MATCH(K16,DB_malas!$A$2:$A$5000,0)),IF(INDEX(DB_materiali!$E$2:$E$5000,MATCH($C16,DB_materiali!$A$2:$A$5000,0))<=INDEX(DB_malas!$D$2:$D$5000,MATCH(K16,DB_malas!$A$2:$A$5000,0)),IF(INDEX(DB_materiali!$B$2:$B$5000,MATCH($C16,DB_materiali!$A$2:$A$5000,0))=INDEX(DB_malas!$B$2:$B$5000,MATCH(K16,DB_malas!$A$2:$A$5000,0)),"✔",tulkojums!$A$38),tulkojums!$A$39),tulkojums!$A$39))
G17: =IF(ISBLANK(C17),"", IFERROR( IF( INDEX(DB_materiali!C$2:C$5000, MATCH(C17, DB_materiali!A$2:A$5000, 0) )="FALSE", "N", "Y" ), "") ) | M17: =IF(ISBLANK(C17),"",IF(IFERROR(VLOOKUP(C17,DB_materiali!$A$2:$A$5000,1,FALSE),"Kļūda artikulā")=C17,"✔",tulkojums!A$42)) | N17: =IF(ISBLANK(C17),"",IF(ISNUMBER(F17)=TRUE,"✔",tulkojums!A$43)) | O17: =IF(ISBLANK(C17),"",IF(G17="Y","✔",IF(G17="X","✔",IF(G17="N","✔",tulkojums!A$44)))) | P17: =IF(ISBLANK(H17),"",IF(INDEX(DB_materiali!$E$2:$E$5000,MATCH($C17,DB_materiali!$A$2:$A$5000,0))>=INDEX(DB_malas!$C$2:$C$5000,MATCH(H17,DB_malas!$A$2:$A$5000,0)),IF(INDEX(DB_materiali!$E$2:$E$5000,MATCH($C17,DB_materiali!$A$2:$A$5000,0))<=INDEX(DB_malas!$D$2:$D$5000,MATCH(H17,DB_malas!$A$2:$A$5000,0)),IF(OR(INDEX(DB_materiali!$B$2:$B$5000,MATCH($C17,DB_materiali!$A$2:$A$5000,0))=INDEX(DB_malas!$B$2:$B$5000,MATCH(H17,DB_malas!$A$2:$A$5000,0)),$H17="ORG"),"✔",tulkojums!$A$38),tulkojums!$A$39),tulkojums!$A$39)) | Q17: =IF(ISBLANK(I17),"",IF(INDEX(DB_materiali!$E$2:$E$5000,MATCH($C17,DB_materiali!$A$2:$A$5000,0))>=INDEX(DB_malas!$C$2:$C$5000,MATCH(I17,DB_malas!$A$2:$A$5000,0)),IF(INDEX(DB_materiali!$E$2:$E$5000,MATCH($C17,DB_materiali!$A$2:$A$5000,0))<=INDEX(DB_malas!$D$2:$D$5000,MATCH(I17,DB_malas!$A$2:$A$5000,0)),IF(OR(INDEX(DB_materiali!$B$2:$B$5000,MATCH($C17,DB_materiali!$A$2:$A$5000,0))=INDEX(DB_malas!$B$2:$B$5000,MATCH(I17,DB_malas!$A$2:$A$5000,0)),$H17="ORG"),"✔",tulkojums!$A$38),tulkojums!$A$39),tulkojums!$A$39)) | R17: =IF(ISBLANK(J17),"",IF(INDEX(DB_materiali!$E$2:$E$5000,MATCH($C17,DB_materiali!$A$2:$A$5000,0))>=INDEX(DB_malas!$C$2:$C$5000,MATCH(J17,DB_malas!$A$2:$A$5000,0)),IF(INDEX(DB_materiali!$E$2:$E$5000,MATCH($C17,DB_materiali!$A$2:$A$5000,0))<=INDEX(DB_malas!$D$2:$D$5000,MATCH(J17,DB_malas!$A$2:$A$5000,0)),IF(INDEX(DB_materiali!$B$2:$B$5000,MATCH($C17,DB_materiali!$A$2:$A$5000,0))=INDEX(DB_malas!$B$2:$B$5000,MATCH(J17,DB_malas!$A$2:$A$5000,0)),"✔",tulkojums!$A$38),tulkojums!$A$39),tulkojums!$A$39)) | S17: =IF(ISBLANK(K17),"",IF(INDEX(DB_materiali!$E$2:$E$5000,MATCH($C17,DB_materiali!$A$2:$A$5000,0))>=INDEX(DB_malas!$C$2:$C$5000,MATCH(K17,DB_malas!$A$2:$A$5000,0)),IF(INDEX(DB_materiali!$E$2:$E$5000,MATCH($C17,DB_materiali!$A$2:$A$5000,0))<=INDEX(DB_malas!$D$2:$D$5000,MATCH(K17,DB_malas!$A$2:$A$5000,0)),IF(INDEX(DB_materiali!$B$2:$B$5000,MATCH($C17,DB_materiali!$A$2:$A$5000,0))=INDEX(DB_malas!$B$2:$B$5000,MATCH(K17,DB_malas!$A$2:$A$5000,0)),"✔",tulkojums!$A$38),tulkojums!$A$39),tulkojums!$A$39))
G18: =IF(ISBLANK(C18),"", IFERROR( IF( INDEX(DB_materiali!C$2:C$5000, MATCH(C18, DB_materiali!A$2:A$5000, 0) )="FALSE", "N", "Y" ), "") ) | M18: =IF(ISBLANK(C18),"",IF(IFERROR(VLOOKUP(C18,DB_materiali!$A$2:$A$5000,1,FALSE),"Kļūda artikulā")=C18,"✔",tulkojums!A$42)) | N18: =IF(ISBLANK(C18),"",IF(ISNUMBER(F18)=TRUE,"✔",tulkojums!A$43)) | O18: =IF(ISBLANK(C18),"",IF(G18="Y","✔",IF(G18="X","✔",IF(G18="N","✔",tulkojums!A$44)))) | P18: =IF(ISBLANK(H18),"",IF(INDEX(DB_materiali!$E$2:$E$5000,MATCH($C18,DB_materiali!$A$2:$A$5000,0))>=INDEX(DB_malas!$C$2:$C$5000,MATCH(H18,DB_malas!$A$2:$A$5000,0)),IF(INDEX(DB_materiali!$E$2:$E$5000,MATCH($C18,DB_materiali!$A$2:$A$5000,0))<=INDEX(DB_malas!$D$2:$D$5000,MATCH(H18,DB_malas!$A$2:$A$5000,0)),IF(OR(INDEX(DB_materiali!$B$2:$B$5000,MATCH($C18,DB_materiali!$A$2:$A$5000,0))=INDEX(DB_malas!$B$2:$B$5000,MATCH(H18,DB_malas!$A$2:$A$5000,0)),$H18="ORG"),"✔",tulkojums!$A$38),tulkojums!$A$39),tulkojums!$A$39)) | Q18: =IF(ISBLANK(I18),"",IF(INDEX(DB_materiali!$E$2:$E$5000,MATCH($C18,DB_materiali!$A$2:$A$5000,0))>=INDEX(DB_malas!$C$2:$C$5000,MATCH(I18,DB_malas!$A$2:$A$5000,0)),IF(INDEX(DB_materiali!$E$2:$E$5000,MATCH($C18,DB_materiali!$A$2:$A$5000,0))<=INDEX(DB_malas!$D$2:$D$5000,MATCH(I18,DB_malas!$A$2:$A$5000,0)),IF(OR(INDEX(DB_materiali!$B$2:$B$5000,MATCH($C18,DB_materiali!$A$2:$A$5000,0))=INDEX(DB_malas!$B$2:$B$5000,MATCH(I18,DB_malas!$A$2:$A$5000,0)),$H18="ORG"),"✔",tulkojums!$A$38),tulkojums!$A$39),tulkojums!$A$39)) | R18: =IF(ISBLANK(J18),"",IF(INDEX(DB_materiali!$E$2:$E$5000,MATCH($C18,DB_materiali!$A$2:$A$5000,0))>=INDEX(DB_malas!$C$2:$C$5000,MATCH(J18,DB_malas!$A$2:$A$5000,0)),IF(INDEX(DB_materiali!$E$2:$E$5000,MATCH($C18,DB_materiali!$A$2:$A$5000,0))<=INDEX(DB_malas!$D$2:$D$5000,MATCH(J18,DB_malas!$A$2:$A$5000,0)),IF(INDEX(DB_materiali!$B$2:$B$5000,MATCH($C18,DB_materiali!$A$2:$A$5000,0))=INDEX(DB_malas!$B$2:$B$5000,MATCH(J18,DB_malas!$A$2:$A$5000,0)),"✔",tulkojums!$A$38),tulkojums!$A$39),tulkojums!$A$39)) | S18: =IF(ISBLANK(K18),"",IF(INDEX(DB_materiali!$E$2:$E$5000,MATCH($C18,DB_materiali!$A$2:$A$5000,0))>=INDEX(DB_malas!$C$2:$C$5000,MATCH(K18,DB_malas!$A$2:$A$5000,0)),IF(INDEX(DB_materiali!$E$2:$E$5000,MATCH($C18,DB_materiali!$A$2:$A$5000,0))<=INDEX(DB_malas!$D$2:$D$5000,MATCH(K18,DB_malas!$A$2:$A$5000,0)),IF(INDEX(DB_materiali!$B$2:$B$5000,MATCH($C18,DB_materiali!$A$2:$A$5000,0))=INDEX(DB_malas!$B$2:$B$5000,MATCH(K18,DB_malas!$A$2:$A$5000,0)),"✔",tulkojums!$A$38),tulkojums!$A$39),tulkojums!$A$39))
G19: =IF(ISBLANK(C19),"", IFERROR( IF( INDEX(DB_materiali!C$2:C$5000, MATCH(C19, DB_materiali!A$2:A$5000, 0) )="FALSE", "N", "Y" ), "") ) | M19: =IF(ISBLANK(C19),"",IF(IFERROR(VLOOKUP(C19,DB_materiali!$A$2:$A$5000,1,FALSE),"Kļūda artikulā")=C19,"✔",tulkojums!A$42)) | N19: =IF(ISBLANK(C19),"",IF(ISNUMBER(F19)=TRUE,"✔",tulkojums!A$43)) | O19: =IF(ISBLANK(C19),"",IF(G19="Y","✔",IF(G19="X","✔",IF(G19="N","✔",tulkojums!A$44)))) | P19: =IF(ISBLANK(H19),"",IF(INDEX(DB_materiali!$E$2:$E$5000,MATCH($C19,DB_materiali!$A$2:$A$5000,0))>=INDEX(DB_malas!$C$2:$C$5000,MATCH(H19,DB_malas!$A$2:$A$5000,0)),IF(INDEX(DB_materiali!$E$2:$E$5000,MATCH($C19,DB_materiali!$A$2:$A$5000,0))<=INDEX(DB_malas!$D$2:$D$5000,MATCH(H19,DB_malas!$A$2:$A$5000,0)),IF(OR(INDEX(DB_materiali!$B$2:$B$5000,MATCH($C19,DB_materiali!$A$2:$A$5000,0))=INDEX(DB_malas!$B$2:$B$5000,MATCH(H19,DB_malas!$A$2:$A$5000,0)),$H19="ORG"),"✔",tulkojums!$A$38),tulkojums!$A$39),tulkojums!$A$39)) | Q19: =IF(ISBLANK(I19),"",IF(INDEX(DB_materiali!$E$2:$E$5000,MATCH($C19,DB_materiali!$A$2:$A$5000,0))>=INDEX(DB_malas!$C$2:$C$5000,MATCH(I19,DB_malas!$A$2:$A$5000,0)),IF(INDEX(DB_materiali!$E$2:$E$5000,MATCH($C19,DB_materiali!$A$2:$A$5000,0))<=INDEX(DB_malas!$D$2:$D$5000,MATCH(I19,DB_malas!$A$2:$A$5000,0)),IF(OR(INDEX(DB_materiali!$B$2:$B$5000,MATCH($C19,DB_materiali!$A$2:$A$5000,0))=INDEX(DB_malas!$B$2:$B$5000,MATCH(I19,DB_malas!$A$2:$A$5000,0)),$H19="ORG"),"✔",tulkojums!$A$38),tulkojums!$A$39),tulkojums!$A$39)) | R19: =IF(ISBLANK(J19),"",IF(INDEX(DB_materiali!$E$2:$E$5000,MATCH($C19,DB_materiali!$A$2:$A$5000,0))>=INDEX(DB_malas!$C$2:$C$5000,MATCH(J19,DB_malas!$A$2:$A$5000,0)),IF(INDEX(DB_materiali!$E$2:$E$5000,MATCH($C19,DB_materiali!$A$2:$A$5000,0))<=INDEX(DB_malas!$D$2:$D$5000,MATCH(J19,DB_malas!$A$2:$A$5000,0)),IF(INDEX(DB_materiali!$B$2:$B$5000,MATCH($C19,DB_materiali!$A$2:$A$5000,0))=INDEX(DB_malas!$B$2:$B$5000,MATCH(J19,DB_malas!$A$2:$A$5000,0)),"✔",tulkojums!$A$38),tulkojums!$A$39),tulkojums!$A$39)) | S19: =IF(ISBLANK(K19),"",IF(INDEX(DB_materiali!$E$2:$E$5000,MATCH($C19,DB_materiali!$A$2:$A$5000,0))>=INDEX(DB_malas!$C$2:$C$5000,MATCH(K19,DB_malas!$A$2:$A$5000,0)),IF(INDEX(DB_materiali!$E$2:$E$5000,MATCH($C19,DB_materiali!$A$2:$A$5000,0))<=INDEX(DB_malas!$D$2:$D$5000,MATCH(K19,DB_malas!$A$2:$A$5000,0)),IF(INDEX(DB_materiali!$B$2:$B$5000,MATCH($C19,DB_materiali!$A$2:$A$5000,0))=INDEX(DB_malas!$B$2:$B$5000,MATCH(K19,DB_malas!$A$2:$A$5000,0)),"✔",tulkojums!$A$38),tulkojums!$A$39),tulkojums!$A$39))
G20: =IF(ISBLANK(C20),"", IFERROR( IF( INDEX(DB_materiali!C$2:C$5000, MATCH(C20, DB_materiali!A$2:A$5000, 0) )="FALSE", "N", "Y" ), "") ) | M20: =IF(ISBLANK(C20),"",IF(IFERROR(VLOOKUP(C20,DB_materiali!$A$2:$A$5000,1,FALSE),"Kļūda artikulā")=C20,"✔",tulkojums!A$42)) | N20: =IF(ISBLANK(C20),"",IF(ISNUMBER(F20)=TRUE,"✔",tulkojums!A$43)) | O20: =IF(ISBLANK(C20),"",IF(G20="Y","✔",IF(G20="X","✔",IF(G20="N","✔",tulkojums!A$44)))) | P20: =IF(ISBLANK(H20),"",IF(INDEX(DB_materiali!$E$2:$E$5000,MATCH($C20,DB_materiali!$A$2:$A$5000,0))>=INDEX(DB_malas!$C$2:$C$5000,MATCH(H20,DB_malas!$A$2:$A$5000,0)),IF(INDEX(DB_materiali!$E$2:$E$5000,MATCH($C20,DB_materiali!$A$2:$A$5000,0))<=INDEX(DB_malas!$D$2:$D$5000,MATCH(H20,DB_malas!$A$2:$A$5000,0)),IF(OR(INDEX(DB_materiali!$B$2:$B$5000,MATCH($C20,DB_materiali!$A$2:$A$5000,0))=INDEX(DB_malas!$B$2:$B$5000,MATCH(H20,DB_malas!$A$2:$A$5000,0)),$H20="ORG"),"✔",tulkojums!$A$38),tulkojums!$A$39),tulkojums!$A$39)) | Q20: =IF(ISBLANK(I20),"",IF(INDEX(DB_materiali!$E$2:$E$5000,MATCH($C20,DB_materiali!$A$2:$A$5000,0))>=INDEX(DB_malas!$C$2:$C$5000,MATCH(I20,DB_malas!$A$2:$A$5000,0)),IF(INDEX(DB_materiali!$E$2:$E$5000,MATCH($C20,DB_materiali!$A$2:$A$5000,0))<=INDEX(DB_malas!$D$2:$D$5000,MATCH(I20,DB_malas!$A$2:$A$5000,0)),IF(OR(INDEX(DB_materiali!$B$2:$B$5000,MATCH($C20,DB_materiali!$A$2:$A$5000,0))=INDEX(DB_malas!$B$2:$B$5000,MATCH(I20,DB_malas!$A$2:$A$5000,0)),$H20="ORG"),"✔",tulkojums!$A$38),tulkojums!$A$39),tulkojums!$A$39)) | R20: =IF(ISBLANK(J20),"",IF(INDEX(DB_materiali!$E$2:$E$5000,MATCH($C20,DB_materiali!$A$2:$A$5000,0))>=INDEX(DB_malas!$C$2:$C$5000,MATCH(J20,DB_malas!$A$2:$A$5000,0)),IF(INDEX(DB_materiali!$E$2:$E$5000,MATCH($C20,DB_materiali!$A$2:$A$5000,0))<=INDEX(DB_malas!$D$2:$D$5000,MATCH(J20,DB_malas!$A$2:$A$5000,0)),IF(INDEX(DB_materiali!$B$2:$B$5000,MATCH($C20,DB_materiali!$A$2:$A$5000,0))=INDEX(DB_malas!$B$2:$B$5000,MATCH(J20,DB_malas!$A$2:$A$5000,0)),"✔",tulkojums!$A$38),tulkojums!$A$39),tulkojums!$A$39)) | S20: =IF(ISBLANK(K20),"",IF(INDEX(DB_materiali!$E$2:$E$5000,MATCH($C20,DB_materiali!$A$2:$A$5000,0))>=INDEX(DB_malas!$C$2:$C$5000,MATCH(K20,DB_malas!$A$2:$A$5000,0)),IF(INDEX(DB_materiali!$E$2:$E$5000,MATCH($C20,DB_materiali!$A$2:$A$5000,0))<=INDEX(DB_malas!$D$2:$D$5000,MATCH(K20,DB_malas!$A$2:$A$5000,0)),IF(INDEX(DB_materiali!$B$2:$B$5000,MATCH($C20,DB_materiali!$A$2:$A$5000,0))=INDEX(DB_malas!$B$2:$B$5000,MATCH(K20,DB_malas!$A$2:$A$5000,0)),"✔",tulkojums!$A$38),tulkojums!$A$39),tulkojums!$A$39))
G21: =IF(ISBLANK(C21),"", IFERROR( IF( INDEX(DB_materiali!C$2:C$5000, MATCH(C21, DB_materiali!A$2:A$5000, 0) )="FALSE", "N", "Y" ), "") ) | M21: =IF(ISBLANK(C21),"",IF(IFERROR(VLOOKUP(C21,DB_materiali!$A$2:$A$5000,1,FALSE),"Kļūda artikulā")=C21,"✔",tulkojums!A$42)) | N21: =IF(ISBLANK(C21),"",IF(ISNUMBER(F21)=TRUE,"✔",tulkojums!A$43)) | O21: =IF(ISBLANK(C21),"",IF(G21="Y","✔",IF(G21="X","✔",IF(G21="N","✔",tulkojums!A$44)))) | P21: =IF(ISBLANK(H21),"",IF(INDEX(DB_materiali!$E$2:$E$5000,MATCH($C21,DB_materiali!$A$2:$A$5000,0))>=INDEX(DB_malas!$C$2:$C$5000,MATCH(H21,DB_malas!$A$2:$A$5000,0)),IF(INDEX(DB_materiali!$E$2:$E$5000,MATCH($C21,DB_materiali!$A$2:$A$5000,0))<=INDEX(DB_malas!$D$2:$D$5000,MATCH(H21,DB_malas!$A$2:$A$5000,0)),IF(OR(INDEX(DB_materiali!$B$2:$B$5000,MATCH($C21,DB_materiali!$A$2:$A$5000,0))=INDEX(DB_malas!$B$2:$B$5000,MATCH(H21,DB_malas!$A$2:$A$5000,0)),$H21="ORG"),"✔",tulkojums!$A$38),tulkojums!$A$39),tulkojums!$A$39)) | Q21: =IF(ISBLANK(I21),"",IF(INDEX(DB_materiali!$E$2:$E$5000,MATCH($C21,DB_materiali!$A$2:$A$5000,0))>=INDEX(DB_malas!$C$2:$C$5000,MATCH(I21,DB_malas!$A$2:$A$5000,0)),IF(INDEX(DB_materiali!$E$2:$E$5000,MATCH($C21,DB_materiali!$A$2:$A$5000,0))<=INDEX(DB_malas!$D$2:$D$5000,MATCH(I21,DB_malas!$A$2:$A$5000,0)),IF(OR(INDEX(DB_materiali!$B$2:$B$5000,MATCH($C21,DB_materiali!$A$2:$A$5000,0))=INDEX(DB_malas!$B$2:$B$5000,MATCH(I21,DB_malas!$A$2:$A$5000,0)),$H21="ORG"),"✔",tulkojums!$A$38),tulkojums!$A$39),tulkojums!$A$39)) | R21: =IF(ISBLANK(J21),"",IF(INDEX(DB_materiali!$E$2:$E$5000,MATCH($C21,DB_materiali!$A$2:$A$5000,0))>=INDEX(DB_malas!$C$2:$C$5000,MATCH(J21,DB_malas!$A$2:$A$5000,0)),IF(INDEX(DB_materiali!$E$2:$E$5000,MATCH($C21,DB_materiali!$A$2:$A$5000,0))<=INDEX(DB_malas!$D$2:$D$5000,MATCH(J21,DB_malas!$A$2:$A$5000,0)),IF(INDEX(DB_materiali!$B$2:$B$5000,MATCH($C21,DB_materiali!$A$2:$A$5000,0))=INDEX(DB_malas!$B$2:$B$5000,MATCH(J21,DB_malas!$A$2:$A$5000,0)),"✔",tulkojums!$A$38),tulkojums!$A$39),tulkojums!$A$39)) | S21: =IF(ISBLANK(K21),"",IF(INDEX(DB_materiali!$E$2:$E$5000,MATCH($C21,DB_materiali!$A$2:$A$5000,0))>=INDEX(DB_malas!$C$2:$C$5000,MATCH(K21,DB_malas!$A$2:$A$5000,0)),IF(INDEX(DB_materiali!$E$2:$E$5000,MATCH($C21,DB_materiali!$A$2:$A$5000,0))<=INDEX(DB_malas!$D$2:$D$5000,MATCH(K21,DB_malas!$A$2:$A$5000,0)),IF(INDEX(DB_materiali!$B$2:$B$5000,MATCH($C21,DB_materiali!$A$2:$A$5000,0))=INDEX(DB_malas!$B$2:$B$5000,MATCH(K21,DB_malas!$A$2:$A$5000,0)),"✔",tulkojums!$A$38),tulkojums!$A$39),tulkojums!$A$39))
G22: =IF(ISBLANK(C22),"", IFERROR( IF( INDEX(DB_materiali!C$2:C$5000, MATCH(C22, DB_materiali!A$2:A$5000, 0) )="FALSE", "N", "Y" ), "") ) | M22: =IF(ISBLANK(C22),"",IF(IFERROR(VLOOKUP(C22,DB_materiali!$A$2:$A$5000,1,FALSE),"Kļūda artikulā")=C22,"✔",tulkojums!A$42)) | N22: =IF(ISBLANK(C22),"",IF(ISNUMBER(F22)=TRUE,"✔",tulkojums!A$43)) | O22: =IF(ISBLANK(C22),"",IF(G22="Y","✔",IF(G22="X","✔",IF(G22="N","✔",tulkojums!A$44)))) | P22: =IF(ISBLANK(H22),"",IF(INDEX(DB_materiali!$E$2:$E$5000,MATCH($C22,DB_materiali!$A$2:$A$5000,0))>=INDEX(DB_malas!$C$2:$C$5000,MATCH(H22,DB_malas!$A$2:$A$5000,0)),IF(INDEX(DB_materiali!$E$2:$E$5000,MATCH($C22,DB_materiali!$A$2:$A$5000,0))<=INDEX(DB_malas!$D$2:$D$5000,MATCH(H22,DB_malas!$A$2:$A$5000,0)),IF(OR(INDEX(DB_materiali!$B$2:$B$5000,MATCH($C22,DB_materiali!$A$2:$A$5000,0))=INDEX(DB_malas!$B$2:$B$5000,MATCH(H22,DB_malas!$A$2:$A$5000,0)),$H22="ORG"),"✔",tulkojums!$A$38),tulkojums!$A$39),tulkojums!$A$39)) | Q22: =IF(ISBLANK(I22),"",IF(INDEX(DB_materiali!$E$2:$E$5000,MATCH($C22,DB_materiali!$A$2:$A$5000,0))>=INDEX(DB_malas!$C$2:$C$5000,MATCH(I22,DB_malas!$A$2:$A$5000,0)),IF(INDEX(DB_materiali!$E$2:$E$5000,MATCH($C22,DB_materiali!$A$2:$A$5000,0))<=INDEX(DB_malas!$D$2:$D$5000,MATCH(I22,DB_malas!$A$2:$A$5000,0)),IF(OR(INDEX(DB_materiali!$B$2:$B$5000,MATCH($C22,DB_materiali!$A$2:$A$5000,0))=INDEX(DB_malas!$B$2:$B$5000,MATCH(I22,DB_malas!$A$2:$A$5000,0)),$H22="ORG"),"✔",tulkojums!$A$38),tulkojums!$A$39),tulkojums!$A$39)) | R22: =IF(ISBLANK(J22),"",IF(INDEX(DB_materiali!$E$2:$E$5000,MATCH($C22,DB_materiali!$A$2:$A$5000,0))>=INDEX(DB_malas!$C$2:$C$5000,MATCH(J22,DB_malas!$A$2:$A$5000,0)),IF(INDEX(DB_materiali!$E$2:$E$5000,MATCH($C22,DB_materiali!$A$2:$A$5000,0))<=INDEX(DB_malas!$D$2:$D$5000,MATCH(J22,DB_malas!$A$2:$A$5000,0)),IF(INDEX(DB_materiali!$B$2:$B$5000,MATCH($C22,DB_materiali!$A$2:$A$5000,0))=INDEX(DB_malas!$B$2:$B$5000,MATCH(J22,DB_malas!$A$2:$A$5000,0)),"✔",tulkojums!$A$38),tulkojums!$A$39),tulkojums!$A$39)) | S22: =IF(ISBLANK(K22),"",IF(INDEX(DB_materiali!$E$2:$E$5000,MATCH($C22,DB_materiali!$A$2:$A$5000,0))>=INDEX(DB_malas!$C$2:$C$5000,MATCH(K22,DB_malas!$A$2:$A$5000,0)),IF(INDEX(DB_materiali!$E$2:$E$5000,MATCH($C22,DB_materiali!$A$2:$A$5000,0))<=INDEX(DB_malas!$D$2:$D$5000,MATCH(K22,DB_malas!$A$2:$A$5000,0)),IF(INDEX(DB_materiali!$B$2:$B$5000,MATCH($C22,DB_materiali!$A$2:$A$5000,0))=INDEX(DB_malas!$B$2:$B$5000,MATCH(K22,DB_malas!$A$2:$A$5000,0)),"✔",tulkojums!$A$38),tulkojums!$A$39),tulkojums!$A$39))
G23: =IF(ISBLANK(C23),"", IFERROR( IF( INDEX(DB_materiali!C$2:C$5000, MATCH(C23, DB_materiali!A$2:A$5000, 0) )="FALSE", "N", "Y" ), "") ) | M23: =IF(ISBLANK(C23),"",IF(IFERROR(VLOOKUP(C23,DB_materiali!$A$2:$A$5000,1,FALSE),"Kļūda artikulā")=C23,"✔",tulkojums!A$42)) | N23: =IF(ISBLANK(C23),"",IF(ISNUMBER(F23)=TRUE,"✔",tulkojums!A$43)) | O23: =IF(ISBLANK(C23),"",IF(G23="Y","✔",IF(G23="X","✔",IF(G23="N","✔",tulkojums!A$44)))) | P23: =IF(ISBLANK(H23),"",IF(INDEX(DB_materiali!$E$2:$E$5000,MATCH($C23,DB_materiali!$A$2:$A$5000,0))>=INDEX(DB_malas!$C$2:$C$5000,MATCH(H23,DB_malas!$A$2:$A$5000,0)),IF(INDEX(DB_materiali!$E$2:$E$5000,MATCH($C23,DB_materiali!$A$2:$A$5000,0))<=INDEX(DB_malas!$D$2:$D$5000,MATCH(H23,DB_malas!$A$2:$A$5000,0)),IF(OR(INDEX(DB_materiali!$B$2:$B$5000,MATCH($C23,DB_materiali!$A$2:$A$5000,0))=INDEX(DB_malas!$B$2:$B$5000,MATCH(H23,DB_malas!$A$2:$A$5000,0)),$H23="ORG"),"✔",tulkojums!$A$38),tulkojums!$A$39),tulkojums!$A$39)) | Q23: =IF(ISBLANK(I23),"",IF(INDEX(DB_materiali!$E$2:$E$5000,MATCH($C23,DB_materiali!$A$2:$A$5000,0))>=INDEX(DB_malas!$C$2:$C$5000,MATCH(I23,DB_malas!$A$2:$A$5000,0)),IF(INDEX(DB_materiali!$E$2:$E$5000,MATCH($C23,DB_materiali!$A$2:$A$5000,0))<=INDEX(DB_malas!$D$2:$D$5000,MATCH(I23,DB_malas!$A$2:$A$5000,0)),IF(OR(INDEX(DB_materiali!$B$2:$B$5000,MATCH($C23,DB_materiali!$A$2:$A$5000,0))=INDEX(DB_malas!$B$2:$B$5000,MATCH(I23,DB_malas!$A$2:$A$5000,0)),$H23="ORG"),"✔",tulkojums!$A$38),tulkojums!$A$39),tulkojums!$A$39)) | R23: =IF(ISBLANK(J23),"",IF(INDEX(DB_materiali!$E$2:$E$5000,MATCH($C23,DB_materiali!$A$2:$A$5000,0))>=INDEX(DB_malas!$C$2:$C$5000,MATCH(J23,DB_malas!$A$2:$A$5000,0)),IF(INDEX(DB_materiali!$E$2:$E$5000,MATCH($C23,DB_materiali!$A$2:$A$5000,0))<=INDEX(DB_malas!$D$2:$D$5000,MATCH(J23,DB_malas!$A$2:$A$5000,0)),IF(INDEX(DB_materiali!$B$2:$B$5000,MATCH($C23,DB_materiali!$A$2:$A$5000,0))=INDEX(DB_malas!$B$2:$B$5000,MATCH(J23,DB_malas!$A$2:$A$5000,0)),"✔",tulkojums!$A$38),tulkojums!$A$39),tulkojums!$A$39)) | S23: =IF(ISBLANK(K23),"",IF(INDEX(DB_materiali!$E$2:$E$5000,MATCH($C23,DB_materiali!$A$2:$A$5000,0))>=INDEX(DB_malas!$C$2:$C$5000,MATCH(K23,DB_malas!$A$2:$A$5000,0)),IF(INDEX(DB_materiali!$E$2:$E$5000,MATCH($C23,DB_materiali!$A$2:$A$5000,0))<=INDEX(DB_malas!$D$2:$D$5000,MATCH(K23,DB_malas!$A$2:$A$5000,0)),IF(INDEX(DB_materiali!$B$2:$B$5000,MATCH($C23,DB_materiali!$A$2:$A$5000,0))=INDEX(DB_malas!$B$2:$B$5000,MATCH(K23,DB_malas!$A$2:$A$5000,0)),"✔",tulkojums!$A$38),tulkojums!$A$39),tulkojums!$A$39))
G24: =IF(ISBLANK(C24),"", IFERROR( IF( INDEX(DB_materiali!C$2:C$5000, MATCH(C24, DB_materiali!A$2:A$5000, 0) )="FALSE", "N", "Y" ), "") ) | M24: =IF(ISBLANK(C24),"",IF(IFERROR(VLOOKUP(C24,DB_materiali!$A$2:$A$5000,1,FALSE),"Kļūda artikulā")=C24,"✔",tulkojums!A$42)) | N24: =IF(ISBLANK(C24),"",IF(ISNUMBER(F24)=TRUE,"✔",tulkojums!A$43)) | O24: =IF(ISBLANK(C24),"",IF(G24="Y","✔",IF(G24="X","✔",IF(G24="N","✔",tulkojums!A$44)))) | P24: =IF(ISBLANK(H24),"",IF(INDEX(DB_materiali!$E$2:$E$5000,MATCH($C24,DB_materiali!$A$2:$A$5000,0))>=INDEX(DB_malas!$C$2:$C$5000,MATCH(H24,DB_malas!$A$2:$A$5000,0)),IF(INDEX(DB_materiali!$E$2:$E$5000,MATCH($C24,DB_materiali!$A$2:$A$5000,0))<=INDEX(DB_malas!$D$2:$D$5000,MATCH(H24,DB_malas!$A$2:$A$5000,0)),IF(OR(INDEX(DB_materiali!$B$2:$B$5000,MATCH($C24,DB_materiali!$A$2:$A$5000,0))=INDEX(DB_malas!$B$2:$B$5000,MATCH(H24,DB_malas!$A$2:$A$5000,0)),$H24="ORG"),"✔",tulkojums!$A$38),tulkojums!$A$39),tulkojums!$A$39)) | Q24: =IF(ISBLANK(I24),"",IF(INDEX(DB_materiali!$E$2:$E$5000,MATCH($C24,DB_materiali!$A$2:$A$5000,0))>=INDEX(DB_malas!$C$2:$C$5000,MATCH(I24,DB_malas!$A$2:$A$5000,0)),IF(INDEX(DB_materiali!$E$2:$E$5000,MATCH($C24,DB_materiali!$A$2:$A$5000,0))<=INDEX(DB_malas!$D$2:$D$5000,MATCH(I24,DB_malas!$A$2:$A$5000,0)),IF(OR(INDEX(DB_materiali!$B$2:$B$5000,MATCH($C24,DB_materiali!$A$2:$A$5000,0))=INDEX(DB_malas!$B$2:$B$5000,MATCH(I24,DB_malas!$A$2:$A$5000,0)),$H24="ORG"),"✔",tulkojums!$A$38),tulkojums!$A$39),tulkojums!$A$39)) | R24: =IF(ISBLANK(J24),"",IF(INDEX(DB_materiali!$E$2:$E$5000,MATCH($C24,DB_materiali!$A$2:$A$5000,0))>=INDEX(DB_malas!$C$2:$C$5000,MATCH(J24,DB_malas!$A$2:$A$5000,0)),IF(INDEX(DB_materiali!$E$2:$E$5000,MATCH($C24,DB_materiali!$A$2:$A$5000,0))<=INDEX(DB_malas!$D$2:$D$5000,MATCH(J24,DB_malas!$A$2:$A$5000,0)),IF(INDEX(DB_materiali!$B$2:$B$5000,MATCH($C24,DB_materiali!$A$2:$A$5000,0))=INDEX(DB_malas!$B$2:$B$5000,MATCH(J24,DB_malas!$A$2:$A$5000,0)),"✔",tulkojums!$A$38),tulkojums!$A$39),tulkojums!$A$39)) | S24: =IF(ISBLANK(K24),"",IF(INDEX(DB_materiali!$E$2:$E$5000,MATCH($C24,DB_materiali!$A$2:$A$5000,0))>=INDEX(DB_malas!$C$2:$C$5000,MATCH(K24,DB_malas!$A$2:$A$5000,0)),IF(INDEX(DB_materiali!$E$2:$E$5000,MATCH($C24,DB_materiali!$A$2:$A$5000,0))<=INDEX(DB_malas!$D$2:$D$5000,MATCH(K24,DB_malas!$A$2:$A$5000,0)),IF(INDEX(DB_materiali!$B$2:$B$5000,MATCH($C24,DB_materiali!$A$2:$A$5000,0))=INDEX(DB_malas!$B$2:$B$5000,MATCH(K24,DB_malas!$A$2:$A$5000,0)),"✔",tulkojums!$A$38),tulkojums!$A$39),tulkojums!$A$39))
... G1000: =IF(ISBLANK(C1000),"", IFERROR( IF( INDEX(DB_materiali!C$2:C$5000, MATCH(C1000, DB_materiali!A$2:A$5000, 0) )="FALSE", "N", "Y" ), "") ) | M1000: =IF(ISBLANK(C1000),"",IF(IFERROR(VLOOKUP(C1000,DB_materiali!$A$2:$A$5000,1,FALSE),"Kļūda artikulā")=C1000,"✔",tulkojums!A$42)) | N1000: =IF(ISBLANK(C1000),"",IF(ISNUMBER(F1000)=TRUE,"✔",tulkojums!A$43)) | O1000: =IF(ISBLANK(C1000),"",IF(G1000="Y","✔",IF(G1000="X","✔",IF(G1000="N","✔",tulkojums!A$44)))) | P1000: =IF(ISBLANK(H1000),"",IF(INDEX(DB_materiali!$E$2:$E$5000,MATCH($C1000,DB_materiali!$A$2:$A$5000,0))>=INDEX(DB_malas!$C$2:$C$5000,MATCH(H1000,DB_malas!$A$2:$A$5000,0)),IF(INDEX(DB_materiali!$E$2:$E$5000,MATCH($C1000,DB_materiali!$A$2:$A$5000,0))<=INDEX(DB_malas!$D$2:$D$5000,MATCH(H1000,DB_malas!$A$2:$A$5000,0)),IF(OR(INDEX(DB_materiali!$B$2:$B$5000,MATCH($C1000,DB_materiali!$A$2:$A$5000,0))=INDEX(DB_malas!$B$2:$B$5000,MATCH(H1000,DB_malas!$A$2:$A$5000,0)),$H1000="ORG"),"✔",tulkojums!$A$38),tulkojums!$A$39),tulkojums!$A$39)) | Q1000: =IF(ISBLANK(I1000),"",IF(INDEX(DB_materiali!$E$2:$E$5000,MATCH($C1000,DB_materiali!$A$2:$A$5000,0))>=INDEX(DB_malas!$C$2:$C$5000,MATCH(I1000,DB_malas!$A$2:$A$5000,0)),IF(INDEX(DB_materiali!$E$2:$E$5000,MATCH($C1000,DB_materiali!$A$2:$A$5000,0))<=INDEX(DB_malas!$D$2:$D$5000,MATCH(I1000,DB_malas!$A$2:$A$5000,0)),IF(OR(INDEX(DB_materiali!$B$2:$B$5000,MATCH($C1000,DB_materiali!$A$2:$A$5000,0))=INDEX(DB_malas!$B$2:$B$5000,MATCH(I1000,DB_malas!$A$2:$A$5000,0)),$H1000="ORG"),"✔",tulkojums!$A$38),tulkojums!$A$39),tulkojums!$A$39)) | R1000: =IF(ISBLANK(J1000),"",IF(INDEX(DB_materiali!$E$2:$E$5000,MATCH($C1000,DB_materiali!$A$2:$A$5000,0))>=INDEX(DB_malas!$C$2:$C$5000,MATCH(J1000,DB_malas!$A$2:$A$5000,0)),IF(INDEX(DB_materiali!$E$2:$E$5000,MATCH($C1000,DB_materiali!$A$2:$A$5000,0))<=INDEX(DB_malas!$D$2:$D$5000,MATCH(J1000,DB_malas!$A$2:$A$5000,0)),IF(INDEX(DB_materiali!$B$2:$B$5000,MATCH($C1000,DB_materiali!$A$2:$A$5000,0))=INDEX(DB_malas!$B$2:$B$5000,MATCH(J1000,DB_malas!$A$2:$A$5000,0)),"✔",tulkojums!$A$38),tulkojums!$A$39),tulkojums!$A$39)) | S1000: =IF(ISBLANK(K1000),"",IF(INDEX(DB_materiali!$E$2:$E$5000,MATCH($C1000,DB_materiali!$A$2:$A$5000,0))>=INDEX(DB_malas!$C$2:$C$5000,MATCH(K1000,DB_malas!$A$2:$A$5000,0)),IF(INDEX(DB_materiali!$E$2:$E$5000,MATCH($C1000,DB_materiali!$A$2:$A$5000,0))<=INDEX(DB_malas!$D$2:$D$5000,MATCH(K1000,DB_malas!$A$2:$A$5000,0)),IF(INDEX(DB_materiali!$B$2:$B$5000,MATCH($C1000,DB_materiali!$A$2:$A$5000,0))=INDEX(DB_malas!$B$2:$B$5000,MATCH(K1000,DB_malas!$A$2:$A$5000,0)),"✔",tulkojums!$A$38),tulkojums!$A$39),tulkojums!$A$39))

Sheet tulkojums
B1: =forma!A1 -> EE
B2: LV
B3: EE
B4: RU
B5: LV | C5: EE | D5: RU
A6: =IF(B$1="LV",B6,IF(B$1="EE",C6,D6)) -> Tellimuse number | B6: Pasūtījuma Nr | C6: Tellimuse number | D6: Номер заказа
A7: =IF(B$1="LV",B7,IF(B$1="EE",C7,D7)) -> Kliendiprojekt nr. | B7: Klienta projekta Nr. | C7: Kliendiprojekt nr. | D7: Название проекта
A8: =IF(B$1="LV",B8,IF(B$1="EE",C8,D8)) -> Kliendi nr. | B8: Klienta Nr. | C8: Kliendi nr. | D8: Номер клиента
A9: =IF(B$1="LV",B9,IF(B$1="EE",C9,D9)) -> Detaili nimetus | B9: Detaļas nosaukums* | C9: Detaili nimetus | D9: Название детали
A10: =IF(B$1="LV",B10,IF(B$1="EE",C10,D10)) -> Tootekood | B10: Materiāla artikuls | C10: Tootekood | D10: Артикул материала
A11: =IF(B$1="LV",B11,IF(B$1="EE",C11,D11)) -> Detaili mõõdud | B11: Detaļas izmēri | C11: Detaili mõõdud | D11: Размеры детали
A12: =IF(B$1="LV",B12,IF(B$1="EE",C12,D12)) -> Pikkus Y | B12: Garums Y | C12: Pikkus Y | D12: Длина Y
A13: =IF(B$1="LV",B13,IF(B$1="EE",C13,D13)) -> Laius X | B13: Platums X | C13: Laius X | D13: Ширина X
A14: =IF(B$1="LV",B14,IF(B$1="EE",C14,D14)) -> Kogus | B14: Skaits | C14: Kogus | D14: Количество
A15: =IF(B$1="LV",B15,IF(B$1="EE",C15,D15)) -> Puidusüü asetsemine | B15: Šķiedras virziens | C15: Puidusüü asetsemine | D15: Направление декора
A16: =IF(B$1="LV",B16,IF(B$1="EE",C16,D16)) -> ABS servakantide paigaldamine | B16: Aplīmēt malas (norādīt malas artikulu) | C16: ABS servakantide paigaldamine | D16: Указать артикул кромки
A17: =IF(B$1="LV",B17,IF(B$1="EE",C17,D17)) -> Pikkus Y1 | B17: Garums Y1 | C17: Pikkus Y1 | D17: Длина Y1
... A23: =IF(B$1="LV",B23,IF(B$1="EE",C23,D23)) -> X-paralleelne laiusega | B23: X-paralēli platumam | C23: X-paralleelne laiusega | D23: X - параллельно ширине
A24: =IF(B$1="LV",B24,IF(B$1="EE",C24,D24)) -> 0 | B24: paraksts | D24: Подпись
A25: =IF(B$1="LV",B25,IF(B$1="EE",C25,D25)) -> Tellimuse kuupäev | B25: Pasūtījuma datums | C25: Tellimuse kuupäev | D25: Дата Заказа
A26: =IF(B$1="LV",B26,IF(B$1="EE",C26,D26)) -> Klient | B26: Pasūtītājs | C26: Klient | D26: Клиент
A27: =IF(B$1="LV",B27,IF(B$1="EE",C27,D27)) -> E-mail | B27: e-pasts | C27: E-mail | D27: е - почта
A28: =IF(B$1="LV",B28,IF(B$1="EE",C28,D28)) -> Mob. | B28: Tālr. | C28: Mob. | D28: Тел.
A29: =IF(B$1="LV",B29,IF(B$1="EE",C29,D29)) -> SUURUS (VALMIS TOOTE) | B29: NORĀDĪTI GATAVO DETAĻU IZMĒRI | C29: SUURUS (VALMIS TOOTE) | D29: ГОТОВЫЕ РАЗМЕРЫ ДЕТАЛЕЙ
A30: =IF(B$1="LV",B30,IF(B$1="EE",C30,D30)) -> Kinnitan tellimust. Suurused ja materjalid on õiged. | B30: 'Pasūtījumu apstiprinu. Izmēri, materiāli pierakstīti precīzi!'' | C30: Kinnitan tellimust. Suurused ja materjalid on õiged. | D30: 'Заказ подтверждаю. Размеры, материал указаны правильно!''
A31: =IF(B$1="LV",B31,IF(B$1="EE",C31,D31)) -> Joonise nr * | B31: Papildus CNC apstrāde (urbšana, frēzēšana) - atzīmēt ar X | C31: Joonise nr * | D31: Чертёж Нр.*
A32: =IF(B$1="LV",B32,IF(B$1="EE",C32,D32)) -> Joonise nr * - Kui on vaja lisatöölemist: puurimine, freesimine. Siis info on joonises! | B32: Detaļas nosaukums* - ja detaļai nepieciešama papildus apstrāde( urbumu urbšana, frēzēšana),detaļas nosaukumu norādīt uz attiecīgā detaļas rasējuma! | C32: Joonise nr * - Kui on vaja lisatöölemist: puurimine, freesimine. Siis info on joonises! | D32: Чертёж Нр.* - Если детали требуют дополнительной обработки: сверление, фрезерование. Oтзыв в чертёж!
A33: =IF(B$1="LV",B33,IF(B$1="EE",C33,D33)) -> Viga kontrollimisel | B33: KĻŪDU PĀRBAUDE | C33: Viga kontrollimisel | D33: Проверка ошибок
A34: =IF(B$1="LV",B34,IF(B$1="EE",C34,D34)) -> Materjali kontroll | B34: Materiāla pārbaude | C34: Materjali kontroll | D34: Проверка материала
A35: =IF(B$1="LV",B35,IF(B$1="EE",C35,D35)) -> Koguse kontrollimine | B35: Skaita pārbaude | C35: Koguse kontrollimine | D35: Проверка количество
A36: =IF(B$1="LV",B36,IF(B$1="EE",C36,D36)) -> Kiudsuuna test | B36: Šķiedras virziena pārbaude | C36: Kiudsuuna test | D36: напр. структ.
... A44: =IF(B$1="LV",B44,IF(B$1="EE",C44,D44)) -> Ei ole õige | B44: Nav korekts | C44: Ei ole õige | D44: Не правильно

Sheet DB_materiali
A1: Artikuls | B1: Dekors | C1: Škiedra | D1: garums | E1: biezums | F1: platums | G1: default_edge_X1 | H1: default_edge_X2
A2: 102.16.0112PE | B2: 0112PE | C2: FALSE | D2: 2800 | E2: 16 | F2: 2070 | S2: Tekstūra | T2: Šķiedra
A3: 102.16.0162PE | B3: 0162PE | C3: FALSE | D3: 2800 | E3: 16 | F3: 2070 | S3: Šķiedra
A4: 102.16.0190PE | B4: 0190PE | C4: FALSE | D4: 2800 | E4: 16 | F4: 2070 | T4: N
A5: 102.16.0375PR | B5: 0375PR | C5: TRUE | D5: 2800 | E5: 16 | F5: 2070 | T5: Y
A6: 102.16.0381PR | B6: 0381PR | C6: TRUE | D6: 2800 | E6: 16 | F6: 2070 | T6: X
A7: 102.16.6459PE | B7: 6459PE | C7: FALSE | D7: 2800 | E7: 16 | F7: 2070
A8: 102.18.0112PE | B8: 0112PE | C8: FALSE | D8: 2800 | E8: 18 | F8: 2070
A9: 102.18.0162PE | B9: 0162PE | C9: FALSE | D9: 2800 | E9: 18 | F9: 2070
A10: 102.18.0164PE | B10: 0164PE | C10: FALSE | D10: 2800 | E10: 18 | F10: 2070
A11: 102.18.0190PE | B11: 0190PE | C11: FALSE | D11: 2800 | E11: 18 | F11: 2070
A12: 102.18.0375PR | B12: 0375PR | C12: TRUE | D12: 2800 | E12: 18 | F12: 2070
A13: 102.18.0381PR | B13: 0381PR | C13: TRUE | D13: 2800 | E13: 18 | F13: 2070
A14: 102.18.6459PE | B14: 6459PE | C14: FALSE | D14: 2800 | E14: 18 | F14: 2070
A15: 102.18.K006PW | B15: K006PW | C15: TRUE | D15: 2800 | E15: 18 | F15: 2070
A16: 102.18.K009PW | B16: K009PW | C16: TRUE | D16: 2800 | E16: 18 | F16: 2070
A17: 102.22.0112PE | B17: 0112PE | C17: FALSE | D17: 2800 | E17: 22 | F17: 2070
A18: 102.25.0112PE | B18: 0112PE | C18: FALSE | D18: 2800 | E18: 25 | F18: 2070
... A40: 73.2.FX0794.20 | B40: FX0794 | C40: FALSE | D40: 3050 | E40: 20 | F40: 1300
A41: 73.8685.16 | B41: 8685 | C41: FALSE | D41: 2800 | E41: 16 | F41: 2070
A42: 73.8685.18 | B42: 8685 | C42: FALSE | D42: 2800 | E42: 18 | F42: 2070
A43: 73.8685.BS.18 | C43: FALSE | D43: 2800 | E43: 18 | F43: 2070
A44: 73.B026.0J.18 | B44: B026 | C44: FALSE | D44: 2800 | E44: 18.1 | F44: 2070
A45: 73.B073.AR.18 | B45: B073AR | C45: FALSE | D45: 2800 | E45: 18.3 | F45: 2070
A46: 73.B073.CH.18 | B46: B073 | C46: FALSE | D46: 2800 | E46: 18.9 | F46: 2070
A47: 73.B073.CH.8 | B47: B073CH | C47: FALSE | D47: 2800 | E47: 8.9 | F47: 2070
A48: 73.B073.IN.18 | B48: B073IN | C48: FALSE | D48: 2800 | E48: 18.6 | F48: 2070
A49: 73.B073.ML.18 | B49: B073ML | C49: TRUE | D49: 2800 | E49: 18.5 | F49: 2070
A50: 73.B073.TA.18 | B50: B073TA | C50: FALSE | D50: 2800 | E50: 18.1 | F50: 2070
A51: 73.B073.WO.18 | B51: B073WO | C51: FALSE | D51: 2800 | E51: 18.4 | F51: 2070
A52: 73.DEFECT.18 | C52: FALSE | D52: 2800 | E52: 18 | F52: 2070
A53: 73.F120.PM.18 | B53: F120 | C53: FALSE | D53: 2800 | E53: 18 | F53: 2070
A54: 73.F128.PA.19 | B54: F128PA | C54: TRUE | D54: 2800 | E54: 19 | F54: 2070
A55: 73.F129.PA.19 | B55: F129PA | C55: TRUE | D55: 2800 | E55: 19 | F55: 2070
A56: 73.F186.10 | B56: F186 | C56: TRUE | D56: 2800 | E56: 10 | F56: 2070
A57: 73.F186.16 | B57: F186 | C57: TRUE | D57: 2800 | E57: 16 | F57: 2070
A58: 73.F186.18 | B58: F186 | C58: TRUE | D58: 2800 | E58: 18 | F58: 2070
A59: 73.F186.25 | B59: F186 | C59: TRUE | D59: 2800 | E59: 25 | F59: 2070
A60: 73.F187.16 | B60: F187 | C60: FALSE | D60: 2800 | E60: 16 | F60: 2070
A61: 73.F187.18 | B61: F187 | C61: TRUE | D61: 2800 | E61: 18 | F61: 2070
...

Sheet DB_malas
A1: Artikuls | B1: Dekors | C1: MIN | D1: MAX
A2: 74.35252.1.45 | B2: 35252 | C2: 8 | D2: 40
A3: 74.38356.1.45 | B3: 38356 | C3: 8 | D3: 40
A4: 74.47981.1.45 | B4: 47981 | C4: 8 | D4: 40
A5: 74.B073.AR.1.23 | B5: B073AR | C5: 8 | D5: 20
A6: 74.B073.CH.1.23 | B6: B073CH | C6: 8 | D6: 20
A7: 74.B073.IN.1.23 | B7: B073IN | C7: 8 | D7: 20
A8: 74.B073.ML.1.23 | B8: B073ML | C8: 8 | D8: 20
A9: 74.B073.WO.1.23 | B9: B073WO | C9: 8 | D9: 20
A10: 74D.U114.1.23 | B10: U114 | C10: 9 | D10: 20
A11: 74D.U114.2.43 | B11: U114 | C11: 8 | D11: 40
A12: 74D.U702.PM.1.23 | B12: U702 | C12: 9 | D12: 20
A13: 74.F011.1.5.43 | B13: F011 | C13: 8 | D13: 40
A14: 74.F012.1.5.43 | B14: F012 | C14: 8 | D14: 40
A15: 74.F014.1.5.43 | B15: F014 | C15: 8 | D15: 40
A16: 74.F021.1.5.43 | B16: F021 | C16: 8 | D16: 40
... A65: 74.F206.PG.1.23 | B65: F206STPG | C65: 9 | D65: 20
A66: 74.F206.PM.1.23 | C66: 9 | D66: 20
A67: 74.F206.PM.1.5.43 | B67: F206PM | C67: 8 | D67: 40
A68: 74.F208.1.5.43 | B68: F208 | C68: 8 | D68: 40
A69: 74.F211.2.42 | B69: F211 | C69: 8 | D69: 40
A70: 74.F212.2.42 | B70: F212 | C70: 8 | D70: 40
A71: 74.F214.2.42 | B71: F214 | C71: 8 | D71: 40
A72: 74.F221.1.5.43 | B72: F221 | C72: 8 | D72: 40
A73: 74.F222.1.5.43 | B73: F222 | C73: 8 | D73: 40
A74: 74.F226.1.5.43 | B74: F226 | C74: 8 | D74: 40
A75: 74.F227.1.5.43 | B75: F227 | C75: 8 | D75: 40
A76: 74.F228.1.5.43 | B76: F228 | C76: 8 | D76: 40
A77: 74.F229.1.5.43 | B77: F229 | C77: 8 | D77: 40
A78: 74.F230.1.5.43 | B78: F230 | C78: 8 | D78: 40
... A152: 74.F620.1.5.43 | B152: F620 | C152: 8 | D152: 40
A153: 74.F627.PM.1.23 | C153: 9 | D153: 20
A154: 74.F637.08.23 | B154: F637 | C154: 9 | D154: 20
A155: 74.F637.1.5.43 | B155: F637 | C155: 8 | D155: 40
A156: 74.F637.2.23 | B156: F637 | C156: 9 | D156: 20
A157: 74.F638.1.5.43 | B157: F638 | C157: 8 | D157: 40
A158: 74.F641.1.5.43 | B158: F641 | C158: 8 | D158: 40
A159: 74.F642.08.23 | B159: F642 | C159: 9 | D159: 20
A160: 74.F642.2.23 | B160: F642 | C160: 9 | D160: 20
A161: 74.F649.08.23 | B161: F649 | C161: 9 | D161: 20
...
